<?xml version="1.0"?>
<sdf version="1.6">
  <model name="rover">
    <link name="base_link">
      <pose>0 0 0 0 0 0</pose>
      <inertial>
        <mass>100.0</mass>
        <inertia>
          <ixx>27.08</ixx>
          <ixy>0</ixy>
          <ixz>0</ixz>
          <iyy>83.33</iyy>
          <iyz>0</iyz>
          <izz>93.75</izz>
        </inertia>
      </inertial>
      <visual name="visual">
        <pose>0 0 0 1.5708 0 0</pose>
        <geometry>
          <box>
            <size>3.0 1.0 1.5</size>
          </box>
        </geometry>
      </visual>
      <collision name="collision">
        <pose>0 0 0 1.5708 0 0</pose>
        <geometry>
          <box>
            <size>3.0 1.0 1.5</size>
          </box>
        </geometry>
      </collision>
    </link>

    <link name="left_rear_wheel_link">
      <pose>0 0 0 0 0 0</pose>
      <inertial>
        <mass>5.0</mass>
        <inertia>
          <ixx>0.41</ixx>
          <ixy>0</ixy>
          <ixz>0</ixz>
          <iyy>0.41</iyy>
          <iyz>0</iyz>
          <izz>0.625</izz>
        </inertia>
      </inertial>
      <visual name="visual">
        <pose>0 0 0 -3.14159 0 0</pose>
        <geometry>
          <cylinder>
            <radius>0.5</radius>
            <length>0.5</length>
          </cylinder>
        </geometry>
      </visual>
      <collision name="collision">
        <pose>0 0 0 -3.14159 0 0</pose>
        <geometry>
          <cylinder>
            <radius>0.5</radius>
            <length>0.5</length>
          </cylinder>
        </geometry>
      </collision>
    </link>

    <link name="left_upper_wheel_link">
      <pose>0 0 0 0 0 0</pose>
      <inertial>
        <mass>5.0</mass>
        <inertia>
          <ixx>0.41</ixx>
          <ixy>0</ixy>
          <ixz>0</ixz>
          <iyy>0.41</iyy>
          <iyz>0</iyz>
          <izz>0.625</izz>
        </inertia>
      </inertial>
      
      <visual name="visual">
        <pose>0 0 0 -3.14159 0 0</pose>
        <geometry>
          <cylinder>
            <radius>0.5</radius>
            <length>0.5</length>
          </cylinder>
        </geometry>
      </visual>
      
      <collision name="collision">
        <pose>0 0 0 -3.14159 0 0</pose>
        <geometry>
          <cylinder>
            <radius>0.5</radius>
            <length>0.5</length>
          </cylinder>
        </geometry>
      </collision>
    </link>

    <link name="right_rear_wheel_link">
      <pose>0 0 0 0 0 0</pose>
      <inertial>
        <mass>5.0</mass>
        <inertia>
          <ixx>0.41</ixx>
          <ixy>0</ixy>
          <ixz>0</ixz>
          <iyy>0.41</iyy>
          <iyz>0</iyz>
          <izz>0.625</izz>
        </inertia>
      </inertial>
      <visual name="visual">
        <pose>0 0 0 -3.14159 0 0</pose>
        <geometry>
          <cylinder>
            <radius>0.5</radius>
            <length>0.5</length>
          </cylinder>
        </geometry>
      </visual>
      <collision name="collision">
        <pose>0 0 0 -3.14159 0 0</pose>
        <geometry>
          <cylinder>
            <radius>0.5</radius>
            <length>0.5</length>
          </cylinder>
        </geometry>
      </collision>
    </link>

    <link name="right_upper_wheel_link">
      <pose>0 0 0 0 0 0</pose>
      <inertial>
        <mass>5.0</mass>
        <inertia>
          <ixx>0.41</ixx>
          <ixy>0</ixy>
          <ixz>0</ixz>
          <iyy>0.41</iyy>
          <iyz>0</iyz>
          <izz>0.625</izz>
        </inertia>
      </inertial>
      <visual name="visual">
        <pose>0 0 0 -3.14159 0 0</pose>
        <geometry>
          <cylinder>
            <radius>0.5</radius>
            <length>0.5</length>
          </cylinder>
        </geometry>
      </visual>
      <collision name="collision">
        <pose>0 0 0 -3.14159 0 0</pose>
        <geometry>
          <cylinder>
            <radius>0.5</radius>
            <length>0.5</length>
          </cylinder>
        </geometry>
      </collision>
    </link>

    <link name="camera_chasis">
      <pose>1.5 0.5 0.75 0 0 0</pose>
      <visual name="visual">
            <geometry>
                <box>
                    <size>0.5 0.5 0.5</size>
                </box>
            </geometry>
        </visual>
        <visual name='cam'>
            <pose>1.5 0.5 0.75 0 0 0</pose>
            <geometry>
                <sphere>
                    <radius>.05</radius>
                </sphere>
            </geometry>
            <material>
              <script>
                <uri>file://media/materials/scripts/gazebo.material</uri>
                <name>Gazebo/Green</name>
              </script>
            </material>
        </visual>
        <sensor name='cam_sensor' type='camera'>
            <pose>1.5 0.5 0.75 0 0 0</pose>
            <update_rate>20.000000</update_rate>
            <camera name='camera'>
                <horizontal_fov>1.570000</horizontal_fov>
                <image>
                    <width>320</width>
                    <height>240</height>
                    <format>R8G8B8</format>
                </image>
                <clip>
                    <near>0.100000</near>
                    <far>15.000000</far>
                </clip>
            </camera>
            <plugin name="camera_controller" filename="libgazebo_ros_camera.so">
                <alwaysOn>true</alwaysOn>
                <updateRate>0.0</updateRate>
                <cameraName>camera_model</cameraName>
                <imageTopicName>image_raw</imageTopicName>
                <cameraInfoTopicName>camera_info</cameraInfoTopicName>
                <frameName>camera_top_body</frameName>
                <hackBaseline>0.07</hackBaseline>
                <distortionK1>0.0</distortionK1>
                <distortionK2>0.0</distortionK2>
                <distortionK3>0.0</distortionK3>
                <distortionT1>0.0</distortionT1>
                <distortionT2>0.0</distortionT2>
            </plugin>
        </sensor>
      </link>

    <joint name="left_rear_wheel_joint" type="continuous">
      <parent>base_link</parent>
      <child>left_rear_wheel_link</child>
      <pose>0 0 0 0 0 0</pose>
      <axis>
        <xyz>0 1 0</xyz>
        <limit>
          <effort>30.0</effort>
          <velocity>3.5</velocity>
        </limit>
      </axis>
    </joint>

    <joint name="left_upper_wheel_joint" type="continuous">
      <parent>base_link</parent>
      <child>left_upper_wheel_link</child>
      <pose>0 0 0 0 0 0</pose>
      <axis>
        <xyz>0 1 0</xyz>
        <limit>
          <effort>30.0</effort>
          <velocity>3.5</velocity>
        </limit>
      </axis>
    </joint>

    <joint name="right_rear_wheel_joint" type="continuous">
      <parent>base_link</parent>
      <child>right_rear_wheel_link</child>
      <pose>0 0 0 0 0 0</pose>
      <axis>
        <xyz>0 1 0</xyz>
        <limit>
          <effort>30.0</effort>
          <velocity>3.5</velocity>
        </limit>
      </axis>
    </joint>

    <joint name="right_upper_wheel_joint" type="continuous">
      <parent>base_link</parent>
      <child>right_upper_wheel_link</child>
      <pose>0 0 0 0 0 0</pose>
      <axis>
        <xyz>0 1 0</xyz>
        <limit>
          <effort>30.0</effort>
          <velocity>3.5</velocity>
        </limit>
      </axis>
    </joint>
  </model>
</sdf>

